# CONTROL DE ERRORES
El control de los errores de código y execución comprende la interpretación de *Seguimientos* y *Excepciones*. Para su posterior edición y depuración.

## Interpretación de Seguimientos
Los Seguimientos los mensajes que retorna un programa cuando ocurre un error, suelen tener los siguientes componentes:
* Todas las rutas de acceso de archivo implicadas, para cada llamada a cada función.
* Los números de línea asociados a cada ruta de acceso de archivo.
* Los nombres de las funciones, métodos o clases implicados en la generación de una excepción.
* El nombre de la excepción que se ha producido.

### Ejemplo 1
    >>> print(var)
    Traceback (most recent call last):
      File "<stdin>", line 1, in <module>
    NameError: name 'var' is not defined. Did you mean: 'vars'?
En este caso intentamos imprimir una variable en la consola. El seguimiento informa primeramente el orden de salida *(most recent call last)*. Luego informa que el código se está ejecutando desde el terminal interactivo <*stdin*> y el error está en la primera línea. Luego menciona la excepción que se produjo *NameError: name 'var' is not defined.* indicando que la variable no fue definida previamente a su llamada. Finalmente, en este caso particular, *Did you mean: 'vars'?* ofrece una posible solución al problema, lo que no siempre se presenta o es viable.

### Ejemplo 2
En un archivo llamado *open.py*, introducimos el siguiente código:
    
    open("text.txt")
Luego lo ejecutamos por consola mediante el comando *python3 open.py*

    Traceback (most recent call last):
      File "/Curso MsBuild/10ControlErrores/open.py", line 1, in <module>
        open("text.txt")
    FileNotFoundError: [Errno 2] No such file or directory: 'text.txt'
El mensaje de seguimiento que retorna, nuevamente indica el orden de salida, pero luego indica el path del archivo que se está ejecutando, y la línea del código que falla. Finalmente, indica que el problema es que el archivo que se intenta ingresar es inexistente.

### Ejemplo 3
Modificamos el archivo open.py para que quede de esta forma:

    def func():
       open("text.txt")
    if True :
        func()
Ahora la instrucción de abrir un archivo está dentro de una fución, y luego aplicamos un condicional que siempre es real, para que mande a llamar a la función. Al ejecutar el archivo por consola, retorna el siguiente mensaje de seguimiento:

    Traceback (most recent call last):
     File "/Curso MsBuild/10ControlErrores/open.py", line 4, in <module>
       func()
     File "/Curso MsBuild/10ControlErrores/open.py", line 2, in func
       open("text.txt")
    FileNotFoundError: [Errno 2] No such file or directory: 'text.txt'
En este caso nos muestra dos líneas de error, primero la cuarta, que es dónde primero se llama a la función con el problema, y luego la línea 2, que es donde efectivamente se define el código que produce el error.

## Control de excepciones
Podemos preveer los errores que se pueden producir y, por ende, el texto específico que arrojará esta excepción en el mensaje de seguimiento. En los dos ejemplos anteriores observamos que cada vez que se intentaba acceder a un archivo inexistente, el seguimiento informaba que se producía la excepción *FileNotFoundError*. Entonces, para que el mensaje de error sea más entendible podemos introducir un código *try - except*:

### Ejemplo 1
    def func():
        try:
            open("text.txt")
        except FileNotFoundError:
            print("El archivo text.txt no existe")
    if True :
     func()
Este código contiene un control de excepción, que le dice a Python que intente (try) ejecutar una instrucción, pero si se presenta una excepción determinada (except FileNotFoundError) entonces, en vez de mostrar el seguimiento del error, ejecute otra instrucción. 

### Ejemplo 2
Pueden agregarse tantas excepciones como sean necesarias, además si no se especifica el mensaje luego del *except*, el código se ejecutará ante cualquier excepción que surja.

    def func():
        try:
            open("text.txt")
        except FileNotFoundError:
            print("El archivo text.txt no existe.")
        except IsADirectoryError:
            print("Imposible acceder a text.txt, es un directorio.")
        except :
            print("Error inesperado.")    
    if True :
        func()
En este caso agregamos tres opciones de excepciones posibles, que el archivo no exista, que en vez de ser un archivo sea un directorio, y una tercera situación sin especificar la excepción, para cualquier otra posibilidad que pueda surgir. 

### Ejemplo 3
Para ahorrar código y no dejar opciones de error muy genéricas, se puede realizar lo siguiente:

    def func():
        try:
            open("text.txt")
        except (FileNotFoundError, IsADirectoryError):
            print("El archivo text.txt no existe, o es inaccesible")
        except Exception as error:
            print("Error inesperado.", error)    
    if True :
        func()
Esta modificación, en primer lugar, agrupamos excepciones, consignándolas entre paréntesis, establecemos que ante cualquiera de ellas, retorne el mismo mensaje de error. Por otra parte, establecemos *except Exception as error:* lo que implica que ante cualquier excepción no especificada que surja, el mensaje de seguimiento de la misma sea almacenado en la variable *error*. Y dentro de la instrucción, imprimimos en pantalla *Error inesperado.* y a continuación el mensaje de seguimiento.

### Ejemplo 4
Las excepciones están agrupadas en Python, por ejemplo *OSError* es una excepción primaria que contiene una gran variedad, entre las que están *FilenotFoundError* y *PermissionError*. Mediante el método anterior, podemos hacer más general nuestra detección de excepciones, y especificar más nuestro código: 

    try:
        open("config.txt")
    except OSError as err:
        if err.errno == 2:
            print("Couldn't find the config.txt file!")
        elif err.errno == 13:
            print("Found config.txt but couldn't read it")
        else:
            print("Unexpected File Error:", err)
El código anterior detectará la excepción primaria *ESError* y su código de seguimiento lo almacena en la variable *err*. Luego mediante el método *.errno* se verifica el número específico del mensaje de seguimiento, y si coincide con alguno de los mencionados, se muestra el mensaje correspondiente. Finalmente, si el número de excepción obtenido del código de seguimiento no coincide con ninguno de los esperados, se envía el mensaje final, con el código en pantalla.